Workbook

Sheet Overview
A1: Aamir Khan: Filmography Overview | AN1: Overall Relationship Classification
A2: Generated 2026-10-08 from the research files. Research cutoff: 2026-09-12. Released feature-film acting appearances through 12 September 2026, including child roles, cameos, song appearances and a voice role. Excluded: the silent short Paranoia (1983); the documentaries Madness in the Desert (2004) and Big in Bollywood (2011); producer-only credits; television; and Lahore 1947 (released 14 August 2026, Wikipedia page now titled Batwara 1947), where he is credited only as producer. Pre-2000 box-office figures come from Wikipedia citations of trade sources and are graded down accordingly. Collaborators covers directors, producers or banners, composers and key writers with at least two of his films, plus directors of historically significant single collaborations. Awards covers documented Filmfare and National Film Award wins for his non-cameo films, all of Aamir Khan's own Filmfare nominations, his wins at other ceremonies, civilian honours, and major international awards and nominations. | AN2: Frictionless idealized romance
AN3: United couple versus external world
A4: Career summary | AN4: Friendship to love
A5: Metric | B5: Value | C5: Method | D5: Notes | AN5: Rivals to lovers
A6: Actor | B6: Aamir Khan | C6: Research file | AN6: Playful conflict masking attraction
A7: Career period | B7: =IF(COUNT(Films!$D$2:$D$58)=0,"n/a",MIN(Films!$D$2:$D$58)&"–"&MAX(Films!$D$2:$D$58)) | C7: Formula | D7: First to latest theatrical release year in Films | AN7: Genuine incompatibility gradually resolved
A8: Research cutoff date | B8: 46277 | C8: Research file | AN8: Established relationship
A9: Total released acting films | B9: =COUNTA(Films!$A$2:$A$58) | C9: Formula | AN9: Marriage under strain
A10: Lead and co-lead films | B10: =COUNTIF(Films!$T$2:$T$58,"Lead")+COUNTIF(Films!$T$2:$T$58,"Co-lead")+COUNTIF(Films!$T$2:$T$58,"Ensemble lead") | C10: Formula | D10: Role Type: Lead, Co-lead, Ensemble lead | AN10: Relationship damaged by mistrust
A11: Supporting roles | B11: =COUNTIF(Films!$T$2:$T$58,"Supporting")+COUNTIF(Films!$T$2:$T$58,"Antagonist") | C11: Formula | D11: Role Type: Supporting, Antagonist | AN11: Relationship manipulated by outsiders
A12: Cameos and special appearances | B12: =COUNTIF(Films!$T$2:$T$58,"Cameo")+COUNTIF(Films!$T$2:$T$58,"Extended special appearance")+COUNTIF(Films!$T$2:$T$58,"Self appearance") | C12: Formula | D12: Role Type: Cameo, Extended special appearance, Self appearance | AN12: Forbidden love
A13: Voice, narration and child roles | B13: =COUNTIF(Films!$T$2:$T$58,"Voice role")+COUNTIF(Films!$T$2:$T$58,"Narrator")+COUNTIF(Films!$T$2:$T$58,"Child role") | C13: Formula | D13: Role Type: Voice role, Narrator, Child role | AN13: Unrequited love
A14: Films with central romance | B14: =COUNTIF(Films!$AE$2:$AE$58,"Central") | C14: Formula | D14: Romance Presence: Central | AN14: Love triangle
A15: Films with major romance | B15: =COUNTIF(Films!$AE$2:$AE$58,"Major") | C15: Formula | D15: Romance Presence: Major | AN15: Tragic lovers
A16: Films with secondary romance | B16: =COUNTIF(Films!$AE$2:$AE$58,"Secondary") | C16: Formula | D16: Romance Presence: Secondary | AN16: Unequal or coercive relationship
A17: Films with minor or implied romance | B17: =COUNTIF(Films!$AE$2:$AE$58,"Minor")+COUNTIF(Films!$AE$2:$AE$58,"Implied") | C17: Formula | D17: Romance Presence: Minor, Implied | AN17: Obsessive pursuit
A18: Films without meaningful romance | B18: =COUNTIF(Films!$AE$2:$AE$58,"None") | C18: Formula | D18: Romance Presence: None | AN18: Romance subordinate to another genre
A19: Distinct principal female co-stars | B19: 40 | C19: Build script | D19: Distinct names in Principal Female Lead or Leads | AN19: Multiple romantic relationships
A20: Romantic pairings recorded | B20: =COUNTA(Romances!$A$2:$A$38) | C20: Formula | AN20: No meaningful romance
A21: Most frequent romantic co-star | B21: Juhi Chawla (6 films) | C21: Build script | D21: Films with a Romances row for her
A22: Most frequent director | B22: Ashutosh Gowariker; Indra Kumar; Mansoor Khan; Zoya Akhtar (3 films each) | C22: Build script
A23: Most frequent producer or production banner | B23: Aamir Khan Productions (11 films) | C23: Build script | D23: From Production Banner
A24: Most frequent music director | B24: A. R. Rahman; Anand–Milind (6 films each) | C24: Build script | D24: From Song Composer
A25: Average pair-friction score | B25: =IFERROR(ROUND(AVERAGE(Romances!$Q$2:$Q$38),1),"n/a") | C25: Formula | D25: Per pairing
A26: Average external-opposition score | B26: =IFERROR(ROUND(AVERAGE(Romances!$S$2:$S$38),1),"n/a") | C26: Formula | D26: Per pairing
A27: Average lover-boy score | B27: =IFERROR(ROUND(AVERAGE(Romances!$V$2:$V$38),1),"n/a") | C27: Formula | D27: Per pairing
A28: Average romance-centrality score | B28: =IFERROR(ROUND(AVERAGE(Films!$AF$2:$AF$58),1),"n/a") | C28: Formula | D28: Per film
A29: Highest-grossing film | B29: Dangal (2016): 2,024 INR crore | C29: Build script | D29: Largest nominal worldwide gross among 14 film(s) reported in INR crore; not inflation-adjusted; 3 film(s) with ranged or disputed figures excluded
A30: Award wins received by the actor | B30: =COUNTIFS(Awards!$I$2:$I$144,"Win",Awards!$G$2:$G$144,"*Aamir Khan*") | C30: Formula | D30: Awards rows whose Recipient includes the actor, in any capacity: acting, directing, producing, honours
A31: Acting award wins | B31: =COUNTIFS(Awards!$I$2:$I$144,"Win",Awards!$G$2:$G$144,"*Aamir Khan*",Awards!$H$2:$H$144,"Actor") | C31: Formula | D31: As above, limited to Recipient Type 'Actor'
A32: Award nominations received by the actor | B32: =COUNTIFS(Awards!$I$2:$I$144,"Nomination",Awards!$G$2:$G$144,"*Aamir Khan*") | C32: Formula | D32: Nominations that did not win
A33: Award wins for his films (all recipients) | B33: =COUNTIF(Awards!$I$2:$I$144,"Win") | C33: Formula
A34: Source-confidence summary (films) | B34: ="High "&COUNTIF(Films!$AS$2:$AS$58,"High")&" · "&"Medium "&COUNTIF(Films!$AS$2:$AS$58,"Medium")&" · "&"Low "&COUNTIF(Films!$AS$2:$AS$58,"Low")&" · "&"Unknown "&COUNTIF(Films!$AS$2:$AS$58,"Unknown") | C34: Formula | D34: Confidence Grade in Films
A35: Sources by reliability tier | B35: ="A "&COUNTIF(Sources!$L$2:$L$215,"A")&" · "&"B "&COUNTIF(Sources!$L$2:$L$215,"B")&" · "&"C "&COUNTIF(Sources!$L$2:$L$215,"C")&" · "&"D "&COUNTIF(Sources!$L$2:$L$215,"D") | C35: Formula | D35: A official · B reputable press · C reference databases · D weak
A37: Career phases
A38: Phase | B38: Years | C38: Films | D38: Summary | E38: Avg lover-boy score
A39: Child actor | B39: 1973–1974 | C39: =COUNTIFS(Films!$D$2:$D$58,">=1973",Films!$D$2:$D$58,"<=1974") | D39: Brief child roles in two films, including the title song of his uncle Nasir Hussain's Yaadon Ki Baaraat. | E39: =IFERROR(ROUND(AVERAGEIFS(Romances!$V$2:$V$38,Romances!$D$2:$D$38,">=1973",Romances!$D$2:$D$38,"<=1974"),1),"n/a")
A40: Early romantic-hero phase | B40: 1984–1994 | C40: =COUNTIFS(Films!$D$2:$D$58,">=1984",Films!$D$2:$D$58,"<=1994") | D40: After the parallel-cinema Holi, Qayamat Se Qayamat Tak made him a teenage romantic lead; most films pair a young couple against feuding or class-proud families, often opposite Juhi Chawla. | E40: =IFERROR(ROUND(AVERAGEIFS(Romances!$V$2:$V$38,Romances!$D$2:$D$38,">=1984",Romances!$D$2:$D$38,"<=1994"),1),"n/a")
A41: Star consolidation and genre range | B41: 1995–2001 | C41: =COUNTIFS(Films!$D$2:$D$58,">=1995",Films!$D$2:$D$58,"<=2001") | D41: Rangeela, Raja Hindustani and Ghulam move him to street-smart and working-class lovers; Sarfarosh, Earth and Lagaan widen his range, and romance becomes one strand among others. | E41: =IFERROR(ROUND(AVERAGEIFS(Romances!$V$2:$V$38,Romances!$D$2:$D$38,">=1995",Romances!$D$2:$D$38,"<=2001"),1),"n/a")
...

Sheet Films
A1: Film ID | B1: Title | C1: Release Date | D1: Release Year | E1: Decade | F1: Language | G1: Genre | H1: Secondary Genre | I1: Runtime | J1: Director | K1: Producer or Producers | L1: Production Banner | M1: Writer or Writers | N1: Source Material or Remake Status | O1: Song Composer | P1: Background-Score Composer | Q1: Lyricist | R1: Actor’s Character | S1: Alternate Identity or Double Role | T1: Role Type | U1: Billing Position | V1: Character Occupation | W1: Character Social Background | X1: Role Gist | Y1: Principal Motivation | Z1: Principal Conflict | AA1: Character Arc | AB1: Moral Alignment | AC1: Character Outcome | AD1: Principal Female Lead or Leads | AE1: Romance Presence | AF1: Romance Centrality Score | AG1: Overall Relationship Classification | AH1: Budget | AI1: Domestic Nett | AJ1: Domestic Gross | AK1: Overseas Gross | AL1: Worldwide Gross | AM1: Currency | AN1: Box-Office Verdict | AO1: Annual Box-Office Rank | AP1: Critical Reception Summary | AQ1: Recognition or Legacy | AR1: Source IDs | AS1: Confidence Grade | AT1: Research Notes
A2: FILM-001 | B2: Yaadon Ki Baaraat | C2: 26977 | D2: 1973 | E2: 1970s | F2: Hindi | G2: Masala | H2: Musical | I2: 168 | J2: Nasir Hussain | K2: Nasir Hussain | L2: Nasir Hussain Films | M2: Salim–Javed; Nasir Hussain | N2: Original | O2: R. D. Burman | Q2: Majrooh Sultanpuri | R2: Young Ratan | S2: Credited as Master Aamir | T2: Child role | W2: Younger version of Ratan (played as an adult by Tariq Khan) | X2: Credited as Master Aamir, the eight-year-old plays the younger Ratan in the flashback built around the title song 'Yaadon Ki Baaraat Nikli Hai', which shows the brothers as children before they are separated. The appearance is brief and has no independent arc; the adult Ratan is played by Tariq Khan. | AA2: Not applicable (brief child role) | AE2: None | AF2: 0 | AG2: No meaningful romance | AM2: INR crore | AO2: 5 | AQ2: Described as the first quintessential masala film; popularised the separated-siblings-reunited formula and launched the careers of Zeenat Aman, Neetu Singh and Tariq Khan. | AR2: SOURCE-004; SOURCE-001 | AS2: Medium | AT2: Release date 9 November 1973 per Wikipedia; Bollywood Hungama lists 3 November 1973. Wikipedia gives box office of ₹5.5 crore (Box Office India) without a nett/gross label, so it is not entered; annual rank 5 refers to that unlabeled measure.
A3: FILM-002 | B3: Madhosh | C3: 1974 | D3: 1974 | E3: 1970s | F3: Hindi | G3: Drama | I3: 133 | J3: Desh Gautam | K3: Tahir Hussain | O3: R. D. Burman | Q3: Majrooh Sultanpuri | R3: Younger Raj | T3: Child role | W3: Younger version of Raj Kumar (played as an adult by Mahendra Sandhu) | X3: Aamir Khan is credited as the younger version of Raj, the lead played by Mahendra Sandhu, in a 1974 drama produced by Tahir Hussain. The sources consulted carry no plot summary and do not describe the child role, so the character's function in the film is unverified beyond the cast credit. | AA3: Not applicable (brief child role) | AE3: None | AF3: 0 | AG3: No meaningful romance | AR3: SOURCE-005; SOURCE-001 | AS3: Low | AT3: Exact release date, writers, box office and reception not found. Wikipedia's article is a stub flagged as needing a plot summary.
A4: FILM-003 | B4: Holi | C4: 30909 | D4: 1984 | E4: 1980s | F4: Hindi | G4: Drama | H4: Coming-of-age | I4: 120 | J4: Ketan Mehta | K4: Pradeep Uppoor | M4: Ketan Mehta; Mahesh Elkunchwar (screenplay) | N4: Based on a play by Marathi playwright Mahesh Elkunchwar | O4: Rajat Dholakia | R4: Madan Sharma | S4: Credited as Aamir Hussain | T4: Ensemble lead | V4: College hostel student | W4: Student in a college hostel | X4: Madan is one of the restless hostel students whose boredom and resentment of the principal escalate into a campus revolt. He joins the protest, is suspended, is implicated after a classmate's suicide and is arrested. The largely improvised parallel-cinema ensemble gave Aamir Khan his first adult screen role, credited as Aamir Hussain. | Y4: Rebellion against the college authorities | Z4: Student protest against the principal and its fallout | AA4: Bored participant in hostel pranks becomes implicated in tragedy | AB4: Morally ambiguous | AC4: Suspended and arrested | AE4: None | AF4: 0 | AG4: No meaningful romance | AP4: Vincent Canby (The New York Times, 1985) found it decently and exuberantly performed by its largely non-professional cast. | AQ4: Wikipedia lists a National Film Award for Best Cinematography (Jehangir Choudhary), flagged as needing a citation. | AR4: SOURCE-006; SOURCE-001 | AS4: Medium | AT4: No budget or box-office data found. Production company not stated.
A5: FILM-004 | B5: Qayamat Se Qayamat Tak | C5: 32262 | D5: 1988 | E5: 1980s | F5: Hindi | G5: Romance | H5: Musical tragedy | I5: 163 | J5: Mansoor Khan | K5: Nasir Hussain | L5: Nasir Hussain Films | M5: Nasir Hussain (story, screenplay); Nuzhat Khan, Aamir Khan (assistant writers) | N5: Original; modern retelling of Layla–Majnun, Heer–Ranjha and Romeo and Juliet | O5: Anand–Milind | Q5: Majrooh Sultanpuri | R5: Rajveer "Raj" Singh | S5: Poses as Roop Singh, Rashmi's intended suitor, at her birthday party | T5: Lead | U5: 1 | V5: Graduate who joins the family clothing business | W5: Rajput family from Dhanakpur, raised in Delhi by his uncle after his father's imprisonment for murder | X5: Raj, the college-educated son of a Rajput family broken by a murder, falls for Rashmi without knowing she belongs to the clan his father wronged. He gatecrashes her birthday under a false name, courts her on holiday and, when both families forbid the match, elopes with her to a ruined fort. Hired killers shoot Rashmi; Raj stabs himself and dies beside her. | Y5: Love for Rashmi and a life free of the family feud | Z5: Loves the daughter of his family's sworn enemy | AA5: Dutiful, wholesome son becomes a lover who defies both families and chooses death over separation | AB5: Heroic | AC5: Dies by suicide beside Rashmi after she is shot | AD5: Juhi Chawla | AE5: Central | AF5: 10 | AG5: Tragic lovers | AH5: 2.5 | AI5: 5 | AM5: INR crore | AN5: Blockbuster | AO5: 3 | AP5: Positive reviews; credited with reinventing the romantic musical and bringing family audiences back to cinemas. | AQ5: Cult classic with a 50-week run; subject of a 2016 book crediting it with reviving Hindi cinema; remade in Telugu, Bangladeshi Bengali, Sinhala and Nepali. | AR5: SOURCE-007 | AS5: Medium | AT5: Budget ₹25 million and domestic nett ₹50 million (The Times of India, via Wikipedia). Wikipedia also lists ₹50 million as worldwide gross without a separate source; not recorded because it duplicates the nett figure. Annual rank 3 (behind Tezaab and Shahenshah) per Box Office India via Wikipedia.
A6: FILM-005 | B6: Raakh | C6: 32619 | D6: 1989 | E6: 1980s | F6: Hindi | G6: Action crime | H6: Revenge drama | I6: 124 | J6: Aditya Bhattacharya | K6: Asif Noor; Sangeeth Sivan; Aditya Bhattacharya | M6: Aditya Bhattacharya; Nuzhat Khan | N6: Original screenplay | P6: Ranjit Barot | R6: Amir Hussein | T6: Lead | U6: 1 | V6: Aimless young man who becomes a vigilante | W6: From a well-off family, leading an otherwise mundane life | X6: Amir is a fearless but aimless young man whose older, more pragmatic girlfriend Neeta is raped by the crime boss Hassan Karmali while he is forced to watch. Guided by a disillusioned policeman, he sets out to wipe out the Karmali family, growing used to violence and even enjoying it. Neeta slowly rebuilds her life; Amir ends on death row. | Y6: Revenge for the assault on Neeta | Z6: Rage at an unjust system against guilt over his own violence | AA6: Innocent, fearless youth becomes a hardened killer | AB6: Anti-hero | AC6: Awaits execution on death row | AD6: Supriya Pathak | AE6: Secondary | AF6: 4 | AG6: Romance subordinate to another genre | AM6: INR crore | AP6: Strong critical acclaim; developed a considerable cult following. | AQ6: Three National Film Awards, including a Special Mention for Aamir Khan (shared with Qayamat Se Qayamat Tak); Bollywood debuts of cinematographer Santosh Sivan and editor A. Sreekar Prasad. | AR6: SOURCE-008 | AS6: Medium | AT6: Shot before but released after Qayamat Se Qayamat Tak. Wikipedia gives box office of ₹15 million (₹1.5 crore) citing Talking Moviez, without a nett/gross label; not entered.
A7: FILM-006 | B7: Love Love Love | C7: 32724 | D7: 1989 | E7: 1980s | F7: Hindi | G7: Romantic action | I7: 146 | J7: Babbar Subhash | K7: Babbar Subhash | L7: B. Subhash Movie Unit | M7: Babbar Subhash | O7: Bappi Lahiri | R7: Amit Verma | T7: Lead | U7: 1 | V7: Student | W7: Poor household with his father, stepmother and sister | X7: Amit, a student from a poor family, falls for his wealthy schoolmate Reema, who is coveted by the violent Vicky. Vicky and his father threaten Amit's family and force the lovers apart, and Amit is humiliated at Reema's engagement party. The couple flee, Amit survives an assassination attempt, and they are reunited after Reema's father kills both antagonists. | Y7: Love for Reema across the class divide | Z7: A violent rival and threats against his family | AA7: Humiliated poor lover persists and survives to win Reema | AB7: Heroic | AC7: Reunited with Reema | AD7: Juhi Chawla | AE7: Central | AF7: 9 | AG7: United couple versus external world | AM7: INR crore | AN7: Average | AP7: Did not match the expectations set by the pair's debut film but was appreciated by viewers. | AQ7: Second film of the Aamir Khan–Juhi Chawla pairing. | AR7: SOURCE-009 | AS7: Medium | AT7: Wikipedia gives box office of ₹2.8 crore citing Indicine, without a nett/gross label; not entered. Budget not found.
A8: FILM-007 | B8: Awwal Number | C8: 33004 | D8: 1990 | E8: 1990s | F8: Hindi | G8: Sports action | I8: 143 | J8: Dev Anand | K8: Dev Anand | M8: Dev Anand | O8: Bappi Lahiri | Q8: Amit Khanna | R8: Sunny | T8: Co-lead | U8: 2 | V8: Cricketer newly selected for the national team | W8: Up-and-coming player replacing an established star | X8: Sunny is a young cricketer picked for India in place of the established star Ronny, who turns vengeful. As DIG Vikram Singh races to stop a terrorist plot to bomb an India–Australia match, Sunny weathers Ronny's hostility and becomes a star by playing the match-winning stroke. A light romance with Aarti offers him emotional support. | Y8: Prove himself in international cricket | Z8: Rivalry with the displaced star Ronny amid a terror plot | AA8: Untested newcomer becomes a match-winner | AB8: Heroic | AC8: Wins the match for India | AD8: Ekta Sohini | AE8: Minor | AF8: 2 | AG8: Romance subordinate to another genre | AP8: A 2019 retrospective blog review treats the film as unintentionally comic. | AR8: SOURCE-010; SOURCE-011; SOURCE-065 | AS8: Low | AT8: Second-billed after Dev Anand. The romance with Aarti (Ekta Sohini) is documented only through the 'I love you' recorder scene, so no Romances row was created. Bollywood Hungama's 1 January 1990 date is a placeholder; Wikipedia's 11 May 1990 is used. No box-office data found.
A9: FILM-008 | B9: Tum Mere Ho | C9: 33018 | D9: 1990 | E9: 1990s | F9: Hindi | G9: Fantasy | H9: Action | I9: 129 | J9: Tahir Hussain | K9: Tahir Hussain | L9: Tahir Hussain Enterprises | M9: Tahir Hussain, M. Kaleem Rahi (screenplay); Tahir Hussain, Surinder Singh (story) | O9: Anand–Milind | Q9: Majrooh Sultanpuri | R9: Shiva | T9: Lead | U9: 1 | V9: Snake charmer | W9: Foundling raised by a poor snake charmer after surviving a serpent's revenge as a baby | X9: Shiva survives a shape-shifting serpent's revenge as a baby and is raised by a poor snake charmer. His music enchants Paro at a fair and they fall in love, but her family reveals she was married as a child and must live as a widow, and her father sends men to kill him. Shiva finally uses his charmer's powers to force the serpent to undo her curse. | Y9: Love for Paro | Z9: Paro's family, the child-widow custom and the serpent's curse | AA9: Cursed foundling becomes a charmer powerful enough to defeat the serpent | AB9: Heroic | AC9: Defeats the serpent; union with Paro implied but not confirmed by sources | AD9: Juhi Chawla | AE9: Central | AF9: 8 | AG9: Forbidden love | AN9: Disaster | AP9: A box-office disaster later enjoyed as a so-bad-it's-good cult film; one 2019 review credits it with using snake tropes to dramatise patriarchal custom. | AR9: SOURCE-012; SOURCE-013 | AS9: Low | AT9: Wikipedia and The Cultural Gutter describe Shiva's origin differently (his father kills the snake versus a stranger stealing its crown); the shared elements are used. The ending is not stated explicitly in either source. No budget or box-office figures found.
A10: FILM-009 | B10: Dil | C10: 33046 | D10: 1990 | E10: 1990s | F10: Hindi | G10: Romantic action | I10: 172 | J10: Indra Kumar | K10: Indra Kumar; Ashok Thakeria | L10: Maruti International | M10: Naushir Khatau (story, screenplay); Rajeev Kaul, Praful Parekh (screenplay); Kamlesh Pandey (dialogue) | O10: Anand–Milind | Q10: Sameer | R10: Raja Prasad | T10: Lead | U10: 1 | V10: College student, later construction worker | W10: Son of Hazari Prasad, a miserly and greedy wastepaper businessman | X10: Raja, the spendthrift son of a miserly scrap dealer, meets the arrogant heiress Madhu at college, fakes blindness to fool her and trades pranks with her. After she falsely accuses him of attempted rape and he rebukes her, they fall in love. Disowned by both fathers, they marry secretly and live in poverty; when Raja is injured, his father tricks Madhu into leaving, but they reunite. | Y10: Love for Madhu | Z10: Both fathers' greed and class pride | AA10: Pleasure-seeking prankster becomes a hard-working husband | AB10: Heroic | AC10: Reunited with Madhu | AD10: Madhuri Dixit | AE10: Central | AF10: 10 | AG10: Rivals to lovers | AH10: 2 | AM10: INR crore | AN10: Highest-grossing film of the year | AO10: 1 | AP10: Positive reviews, with praise for the soundtrack and cast performances. | AQ10: Madhuri Dixit's first Filmfare Best Actress award; soundtrack sold about 2 million units; remade in Telugu (Tholi Muddu) and Kannada (Shivaranjani). | AR10: SOURCE-014 | AS10: Medium | AT10: Wikipedia gives two release dates (15 and 22 June 1990); the infobox date 22 June is used, matching Bollywood Hungama. Box office 'est. ₹20 crore' (Box Office India via Wikipedia) has no nett/gross label and is not entered.
A11: FILM-010 | B11: Deewana Mujh Sa Nahin | C11: 33074 | D11: 1990 | E11: 1990s | F11: Hindi | G11: Romantic action | I11: 130 | J11: Y. Nageshwar Rao | K11: Aji | L11: Vandana Productions | M11: M. Parvez | N11: Remake of the 1986 Pakistani film Beyqaraar | O11: Anand–Milind | Q11: Sameer | R11: Ajay Sharma | T11: Lead | U11: 1 | V11: Photographer at a modelling agency | X11: Ajay, a photographer at a modelling agency, becomes convinced that his colleague Anita returns his love, though she sees him only as a friend. When she becomes engaged to Vikram, Ajay keeps preparing to marry her anyway, and she must act to stop his obsession. Events expose that Vikram does not love her and that Ajay's devotion is sincere, and the film ends happily with them together. | Y11: Marry Anita | Z11: Anita does not love him and is engaged to Vikram | AA11: Deluded, fixated admirer is finally accepted | AB11: Sympathetic but obsessive | AC11: Wins Anita | AD11: Madhuri Dixit | AE11: Central | AF11: 9 | AG11: Obsessive pursuit | AR11: SOURCE-015 | AS11: Low | AT11: No budget, box-office, reception or award data found. Plot detail comes from a short Wikipedia synopsis.
A12: FILM-011 | B12: Jawani Zindabad | C12: 33102 | D12: 1990 | E12: 1990s | F12: Hindi | G12: Romantic action | H12: Social drama | I12: 163 | J12: Arun Bhatt | K12: Jay Mehta | L12: Prathima Films | M12: Bhushan Vanmali | N12: Remake of the Kannada film Avale Nanna Hendthi (1988) | O12: Anand–Milind | R12: Shashi Sharma | T12: Lead | U12: 1 | V12: Office worker | W12: Family scarred by dowry: his elder sister died a dowry victim | X12: Shashi, whose elder sister died as a victim of dowry, vows never to give or take dowry. Defying his mother, he marries Sugandha without any dowry, then takes on the greedy in-laws of his younger sister Rama, led by the politician Goverdhan Verma. Seriously injured in the confrontation, he survives to see Goverdhan reform. | Y12: End the dowry practice that killed his sister | Z12: Protecting Rama from her in-laws' greed | AA12: A principled young man holds to his vow against family pressure and political power | AB12: Heroic | AC12: Survives serious injuries; Goverdhan reforms | AD12: Farha Naaz | AE12: Secondary | AF12: 4 | AG12: Romance subordinate to another genre | AR12: SOURCE-016 | AS12: Low | AT12: Marriage to Sugandha is documented, but not how they meet. No box-office, reception or award data found.
A13: FILM-012 | B13: Afsana Pyar Ka | C13: 33354 | D13: 1991 | E13: 1990s | F13: Hindi | G13: Romantic drama | I13: 145 | J13: M. R. Shahjahan | K13: Manoj Seksaria; Sanjay Seksaria; Arvind Seksaria | M13: Bono Deb (story, screenplay); Ramesh Pant (dialogue) | O13: Bappi Lahiri | Q13: Sameer; Anjaan | R13: Raj | T13: Lead | U13: 1 | V13: College student | W13: Raised by his father Mahendra Behl, apart from the mother who left him as an infant | X13: Raj and Nikita meet at college and, after early misunderstandings, fall in love without knowing their families share a long-standing feud. Raj also does not realise that the college's new principal is the mother who left him with his father. When both families forbid the marriage and arrange other matches, the couple decide to elope. | Y13: Marry Nikita | Z13: Feuding families refuse the match | AA13: A college romance becomes open defiance of both families | AB13: Heroic | AC13: Elopes with Nikita; later events not verified | AD13: Neelam | AE13: Central | AF13: 9 | AG13: Forbidden love | AR13: SOURCE-017; SOURCE-065 | AS13: Low | AT13: The family backstory and elopement come from web search summaries of IMDb-style plot synopses. The songs 'Nazren Mili' and 'Tip Tip Tip Tip Baarish Shuru Ho Gayi' were popular. No box-office data found.
A14: FILM-013 | B14: Dil Hai Ke Manta Nahin | C14: 33431 | D14: 1991 | E14: 1990s | F14: Hindi | G14: Romantic comedy | H14: Road film | I14: 151 | J14: Mahesh Bhatt | K14: Gulshan Kumar; Mukesh Bhatt | L14: T-Series; Vishesh Films | M14: Robin Bhatt; Sharad Joshi | N14: Adaptation of It Happened One Night (1934) and Chori Chori (1956) | O14: Nadeem–Shravan | Q14: Sameer; Faaiz Anwar; Rani Malik; Aziz Khan | R14: Raghu Jetley | T14: Lead | U14: 1 | V14: Journalist who has just lost his job | W14: Working-class and financially insecure | X14: Raghu, a newly unemployed journalist, recognises a runaway heiress on a bus and forces a bargain: he will help her reach her film-star fiancé in exchange for an exclusive story. The road trip turns bickering into love. When he leaves to raise money so he can propose, she believes he has used her and returns to marry the star, until her father reveals Raghu's integrity. | Y14: An exclusive story to rescue his career, then love for Pooja | Z14: Has no money or standing to marry the heiress he has fallen for | AA14: Opportunistic blackmailer becomes a devoted, scrupulous lover | AB14: Morally grey to heroic | AC14: Pooja leaves her wedding to marry him with her father's blessing | AD14: Pooja Bhatt | AE14: Central | AF14: 9 | AG14: Playful conflict masking attraction | AM14: INR crore | AN14: Box office success | AP14: A commercial success whose soundtrack was praised; boosted Pooja Bhatt's career and consolidated Aamir Khan's stardom. | AQ14: Remade in Telugu as Kurradi Kurrodu (1994) and Tamil as Kadhal Rojavae (2000). | AR14: SOURCE-018; SOURCE-019 | AS14: Medium | AT14: Wikipedia gives box office of ₹42 million (₹4.2 crore) citing Box Office India, without saying whether it is nett or gross; Box Office India's own film page shows no figures. Not entered in any commercial column. Runtime from Box Office India. Filmfare: Best Actor nomination for Aamir Khan.
A15: FILM-014 | B15: Daulat Ki Jung | C15: 33620 | D15: 1992 | E15: 1990s | F15: Hindi | G15: Action adventure | J15: S. A. Kader | K15: Jalil Ahmed | N15: Inspired by Mackenna's Gold (1969) | O15: Anand–Milind | Q15: Majrooh Sultanpuri | R15: Rajesh Chaudhry | T15: Lead | U15: 1 | V15: College student | W15: Son of the wealthy businessman Bhushan Chaudhry | X15: Rajesh, the son of a wealthy businessman, loves his classmate Asha, whose father is his father's business rival. When both fathers clamp down on them, the couple elope in a stolen car and stumble into a treasure hunt around a tribal village, pursued by crooks. An undercover police officer disposes of the criminals and the lovers are united. | Y15: Be with Asha | Z15: Rival fathers and treasure-hunting criminals | AA15: Sheltered rich son becomes a fugitive lover | AB15: Heroic | AC15: United with Asha | AD15: Juhi Chawla | AE15: Central | AF15: 7 | AG15: United couple versus external world | AN15: Box office failure | AR15: SOURCE-020 | AS15: Low | AT15: Release date 17 January 1992 per Wikipedia; Bollywood Hungama lists 3 January 1992. Runtime, writers and box-office figures not found.
A16: FILM-015 | B16: Jo Jeeta Wohi Sikandar | C16: 33746 | D16: 1992 | E16: 1990s | F16: Hindi | G16: Sports drama | H16: Coming-of-age | I16: 169 | J16: Mansoor Khan | K16: Nasir Hussain | L16: Nasir Hussain Films | M16: Nasir Hussain; Mansoor Khan | N16: Original; resemblance to Breaking Away (1979) noted after release | O16: Jatin–Lalit | Q16: Majrooh Sultanpuri | R16: Sanjaylal "Sanju" Sharma | T16: Lead | U16: 1 | V16: Student at Model College | W16: Middle-class son of Ramlal Sharma; younger brother of the college's star cyclist Ratan | X16: Sanju is a carefree Model College student living in the shadow of his brother Ratan and the elite Rajput College. He fakes wealth to date the rich Devika, ignoring his loyal friend Anjali's warnings, and is humiliated when exposed. After Ratan is badly injured in the rivalry, a chastened Sanju takes his place in the inter-college cycle race and wins it in the final seconds. | Y16: Status and fun, later redemption for his brother and father | Z16: Class rivalry with Rajput College and its champion Shekhar | AA16: Irresponsible show-off becomes a disciplined, humbled champion | AB16: Flawed, redeemed | AC16: Wins the cycle race for Model College | AD16: Ayesha Jhulka; Pooja Bedi | AE16: Major | AF16: 6 | AG16: Multiple romantic relationships | AM16: INR crore | AN16: Commercially successful | AP16: The Indian Express (1992) praised the cinematography, sets and performances of Aamir Khan, Ayesha Jhulka and Pooja Bedi but criticised the music. | AQ16: Cult following; often cited among the best Indian coming-of-age films. Filmfare Best Film. | AR16: SOURCE-021 | AS16: Medium | AT16: Wikipedia gives India box office of ₹70 million (₹7 crore), citing Bollywood Hungama and Box Office India, without a nett/gross label; not entered.
A17: FILM-016 | B17: Isi Ka Naam Zindagi | C17: 33844 | D17: 1992 | E17: 1990s | F17: Hindi | G17: Supernatural action comedy | I17: 145 | J17: Kalidas | K17: Ratan Mukherjee | N17: Remake of the Bengali film Banchharamer Bagaan (1980), based on Manoj Mitra's play Shajano Bagaan | O17: Bappi Lahiri | Q17: Ramesh Pant | R17: Chhotu | T17: Co-lead | U17: 1 | W17: Grandson of Bansiram, who guards a coveted plot of land | X17: Chhotu is the grandson of Bansiram, an old man who refuses to surrender a prized plot of land to successive heirs of a zamindar family. The film's weight rests on Pran's Bansiram, and later comment describes Aamir Khan's part as largely inconsequential, relegated to songs and a romance with Chumki. No detailed account of Chhotu's own arc was found. | AD17: Farah | AE17: Minor | AF17: 3 | AG17: Romance subordinate to another genre | AM17: INR crore | AN17: Box office failure | AP17: Pran's performance was singled out and used to promote the film. | AR17: SOURCE-022; SOURCE-065 | AS17: Low | AT17: Billed first but functions as a co-lead to Pran. Wikipedia gives box office of ₹18 million (Indicine) without a nett/gross label; not entered. No Romances row because the relationship with Chumki is undocumented beyond the cast list.
A18: FILM-017 | B18: Damini | C18: 34089 | D18: 1993 | E18: 1990s | F18: Hindi | G18: Legal drama | I18: 150 | J18: Rajkumar Santoshi | K18: Karim Morani; Bunty Soorma; Ali Morani | L18: Cineyug Films | M18: Rajkumar Santoshi (story, screenplay); Sutanu Gupta (story); Dilip Shukla (dialogue) | O18: Nadeem–Shravan | P18: Vanraj Bhatia | Q18: Sameer | R18: Himself | T18: Self appearance | X18: Aamir Khan appears as himself in the stage-show dance number 'Bin Sajan Jhoola Jhoolu' in Rajkumar Santoshi's legal drama. The appearance doubles as promotion for his then-upcoming Santoshi film Andaz Apna Apna and has no narrative function. The drama itself, led by Meenakshi Seshadri and Sunny Deol, is regarded as a cult feminist film and won National Film and Filmfare awards. | AE18: None | AF18: 0 | AG18: No meaningful romance | AM18: INR crore | AP18: Universal acclaim for its execution and performances; regarded as a cult feminist film. | AQ18: National Film Award for Best Supporting Actor (Sunny Deol); Filmfare Best Director, Supporting Actor, Story and Sound. | AR18: SOURCE-023 | AS18: Medium | AT18: Wikipedia's 'est. ₹11.75 crore' box office has no nett/gross label and is not entered.
A19: FILM-018 | B19: Parampara | C19: 34103 | D19: 1993 | E19: 1990s | F19: Hindi | G19: Action drama | I19: 155 | J19: Yash Chopra | K19: Firoz A. Nadiadwala | M19: Honey Irani (story, screenplay); Aditya Chopra (screenplay); Rahi Masoom Raza (dialogue) | O19: Shiv–Hari | R19: Ranvir Prithvi Singh | T19: Co-lead | V19: College student | W19: Son of Prithvi Singh and the gypsy woman Tara, raised in the Thakur household after her death | X19: Ranvir, son of Prithvi Singh and the gypsy woman Tara, grows up in the Thakur household alongside his half-brother Pratap. On learning who ordered his mother's execution, he turns on Pratap and a violent feud engulfs the family. After the patriarch's death the brothers embrace and the bloodshed ends. | Y19: Justice for his mother's death | Z19: Feud with his half-brother Pratap over the family's past | AA19: Unaware youth becomes vengeful, then reconciles | AB19: Morally conflicted | AC19: Reconciles with Pratap | AE19: Minor | AF19: 2 | AG19: Romance subordinate to another genre | AN19: Flop | AP19: Largely negative reviews; one review singled out Aamir Khan's performance while calling the younger cast out of place. | AR19: SOURCE-024; SOURCE-065 | AS19: Low | AT19: Neelam (Sapna) and Raveena Tandon (Vijaya) appear, but no source consulted documents a romantic pairing for Ranvir, so Principal Female Lead is left blank and no Romances row was created. Saif Ali Khan's Hindi film debut. No box-office figures found.
A20: FILM-019 | B20: Hum Hain Rahi Pyar Ke | C20: 34173 | D20: 1993 | E20: 1990s | F20: Hindi | G20: Romantic comedy-drama | I20: 150 | J20: Mahesh Bhatt | K20: Tahir Hussain | L20: Tahir Hussain Enterprises | M20: Robin Bhatt (story, screenplay, dialogue); Aamir Khan (screenplay, dialogue) | N20: Based on Houseboat (1958) | O20: Nadeem–Shravan | P20: Shyam–Surender; Nadeem–Shravan | Q20: Sameer | R20: Rahul Malhotra | T20: Lead | U20: 1 | V20: Runs a garment company under pressure to deliver a large shirt order | W20: Guardian of his late sister's three mischievous children | X20: Rahul, struggling to run a garment business and control his late sister's three unruly children, agrees to marry the businessman Bijlani's daughter Maya for the children's sake. The children secretly shelter Vyjayanti, who has escaped her father's confinement, and she wins them over and then Rahul. Surviving sabotage by the spurned Bijlanis and her tradition-bound father's resistance, Rahul marries Vyjayanti. | Y20: Keep the business afloat and give the children a stable home | Z20: Obligation to the Bijlanis against love for Vyjayanti | AA20: Stern, overwhelmed guardian becomes a warm father figure and partner | AB20: Heroic | AC20: Completes the order despite sabotage and marries Vyjayanti | AD20: Juhi Chawla | AE20: Central | AF20: 8 | AG20: Friendship to love | AM20: INR crore | AP20: Positive reviews, with particular praise for Juhi Chawla's performance. | AQ20: National Film Awards: Special Jury Award (Mahesh Bhatt) and Best Female Playback Singer (Alka Yagnik). Filmfare Best Film and Best Actress. Soundtrack sold 2.5 million units. Remade in Telugu and Malayalam. | AR20: SOURCE-025 | AS20: Medium | AT20: Aamir Khan co-wrote the screenplay and dialogue. Wikipedia's ₹97 million box office (Box Office India) has no nett/gross label and is not entered.
A21: FILM-020 | B21: Pehla Nasha | C21: 34194 | D21: 1993 | E21: 1990s | F21: Hindi | G21: Thriller | I21: 131 | J21: Ashutosh Gowariker | K21: Mohammed A. Rahim; Viral Shah | M21: Neeraj Vora (story); Ashutosh Gowariker (screenplay); Sanjay Chhel (dialogue) | N21: Remake of Body Double (1984) | O21: Uttankk V. Vora; Neeraj Vora | Q21: Anand Bakshi | R21: Himself | T21: Self appearance | X21: Aamir Khan appears as himself in a scene with Shah Rukh Khan, Saif Ali Khan, Rahul Roy and Sudesh Berry in Ashutosh Gowariker's directorial debut, a remake of Body Double. It is noted as the only film to put Aamir, Shah Rukh and Saif Khan in a single scene; the cameo has no narrative role. | AE21: None | AF21: 0 | AG21: No meaningful romance | AN21: Failure | AP21: Negative reviews. | AR21: SOURCE-026 | AS21: Medium | AT21: First collaboration with Ashutosh Gowariker as director. No box-office figures found.
A22: FILM-021 | B22: Andaz Apna Apna | C22: 34642 | D22: 1994 | E22: 1990s | F22: Hindi | G22: Comedy | H22: Action | I22: 160 | J22: Rajkumar Santoshi | K22: Vinay Kumar Sinha | L22: Vinay Pictures | M22: Rajkumar Santoshi; Dilip Shukla | O22: Tushar Bhatia | P22: Viju Shah | Q22: Majrooh Sultanpuri | R22: Amar Manohar | S22: Uses the alias Teelu; feigns amnesia and blindness | T22: Lead | U22: 1 | V22: Unemployed daydreamer | W22: Lives with his father Murli Manohar | X22: Amar, a lazy daydreamer, sets out to marry the heiress Raveena Bajaj for her father's money and meets his match in the equally scheming Prem. Unaware that Raveena and her secretary Karishma have swapped identities, he falls for the woman he believes is the heiress. Through feigned amnesia, rival cons and a villainous twin, he ends up marrying the real Karishma for love. | Y22: Get rich by marrying an heiress | Z22: Rivalry with Prem for the heiress | AA22: Gold-digger falls genuinely in love and becomes a reluctant hero | AB22: Comic rogue | AC22: Marries Karishma | AD22: Raveena Tandon; Karisma Kapoor | AE22: Major | AF22: 6 | AG22: Romance subordinate to another genre | AH22: 2.9 | AJ22: 8.18 | AL22: 8.653 | AM22: INR crore | AN22: Commercially unsuccessful | AP22: Unsuccessful on release; later praised as one of the greatest Hindi comedies (Raja Sen, Khalid Mohamed). | AQ22: Cult classic; voted second-best Bollywood comedy in an Indian Express online poll; 4K re-release on 25 April 2025. | AR22: SOURCE-027; SOURCE-065 | AS22: Medium | AT22: Box Office India via Wikipedia: budget ₹29 million, domestic ₹8.18 crore, overseas US$150,000, worldwide gross ₹8.653 crore. The domestic figure is recorded as gross because it plus overseas approximates the worldwide gross. Release date 4 November 1994 per Wikipedia; Bollywood Hungama lists 3 September 1994. Raveena Tandon plays Karishma, the secretary posing as the heiress; she is Amar's partner.
A23: FILM-022 | B23: Baazi | C23: 34803 | D23: 1995 | E23: 1990s | F23: Hindi | G23: Action thriller | I23: 180 | J23: Ashutosh Gowariker | K23: Salim Akhtar | L23: Aftab Pictures | M23: Ashutosh Gowariker; Neeraj Vora; Naushil Mehta (writers); Santosh Saroj (dialogue) | N23: Original; critics likened it to Die Hard | O23: Anu Malik | P23: Aadesh Shrivastava | Q23: Majrooh Sultanpuri; Anwar Sagar | R23: Inspector Amar Damjee Rathod | S23: Goes undercover in drag as Miss Julie Braganza | T23: Lead | U23: 1 | V23: Police inspector | W23: Son of a police inspector; both parents were murdered by Chaubey | X23: Inspector Amar, whose parents were murdered by the politician Chaubey, investigates a multi-crore scandal and is framed for killing the police commissioner's daughter. Hunted, he works undercover, including in drag as Miss Julie Braganza, and fights through a hostage siege that endangers journalist Sanjana. He electrocutes Chaubey in the climax and is honoured by the Chief Minister. | Y23: Expose the scandal and avenge his parents | Z23: Framed and hunted by a powerful politician | AA23: Dedicated officer becomes a fugitive and avenger | AB23: Heroic | AC23: Kills Chaubey and is honoured | AD23: Mamta Kulkarni | AE23: Secondary | AF23: 3 | AG23: Romance subordinate to another genre | AH23: 3.25 | AM23: INR crore | AP23: Mixed reviews; India Today called it an ambitious collage of Die Hard, Point Break and Rambo that 'just doesn't work'. | AR23: SOURCE-028 | AS23: Medium | AT23: Budget ₹32.50 million; box office 'est. ₹88 million' (boxofficeindia.com via Wikipedia) has no nett/gross label and is not entered. Release date 14 April 1995 per Wikipedia; Bollywood Hungama lists 13 April.
A24: FILM-023 | B24: Aatank Hi Aatank | C24: 34915 | D24: 1995 | E24: 1990s | F24: Hindi | G24: Action crime | I24: 155 | J24: Dilip Shankar | K24: Mangal; Xavier Marquis (presenter) | L24: Suyash Films | M24: Dilip Shankar | N24: Heavily inspired by The Godfather (1972) | O24: Bappi Lahiri | Q24: Naqsh Lyallpuri; Anwar Sagar; Sanam Ghazipuri; others | R24: Rohan | T24: Co-lead | U24: 2 | V24: Son of a crime boss who becomes one himself | W24: Younger son of the crime patriarch Shiv Charan Sharma | X24: Rohan, the younger son of crime patriarch Shiv Charan Sharma, has kept away from the family business until his father is shot. He takes revenge on the rival Gogia Advani, goes on the run, and four years later has become a crime lord alongside his brother Munna. His girlfriend Neha and a later attraction to Ganga sit at the margins of this Godfather-inspired gang war. | Y24: Avenge the attack on his father | Z24: Gang war with rival dons | AA24: Outsider son becomes a crime lord | AB24: Anti-hero | AD24: Juhi Chawla; Pooja Bedi | AE24: Minor | AF24: 3 | AG24: Romance subordinate to another genre | AN24: Box office failure | AR24: SOURCE-029 | AS24: Low | AT24: Second-billed after Rajinikanth. Relationships with Neha (Juhi Chawla) and Ganga (Pooja Bedi) are documented only as one-line cast descriptions, so no Romances rows were created. Ending, box-office figures and reviews not found.
A25: FILM-024 | B25: Rangeela | C25: 34950 | D25: 1995 | E25: 1990s | F25: Hindi | G25: Musical | H25: Romantic drama | I25: 150 | J25: Ram Gopal Varma | K25: Jhamu Sughand; Ram Gopal Varma | L25: Varma Creations | M25: Ram Gopal Varma (story, screenplay); Neeraj Vora, Sanjay Chhel (dialogue) | O25: A. R. Rahman | P25: A. R. Rahman | Q25: Mehboob | R25: Munna | T25: Lead | U25: 1 | V25: Black-market cinema ticket seller | W25: Streetwise Mumbai orphan (tapori) | X25: Munna, a streetwise orphan who sells cinema tickets on the black market, has loved his childhood friend Mili for years without saying so. When Mili starts working with the star Raj Kamal, Munna's sense of inferiority deepens as she spends her days with Raj, and every attempt to confess fails. He writes a farewell letter and leaves town, but Mili reads it and, with Raj's help, reaches him. | Y25: Love for Mili | Z25: Cannot confess his love while a film star seems to offer Mili a better life | AA25: Insecure tapori finds the courage to reveal his feelings | AB25: Heroic | AC25: Reunited with Mili | AD25: Urmila Matondkar | AE25: Central | AF25: 9 | AG25: Love triangle | AH25: 4.5 | AM25: INR crore | AN25: Blockbuster | AO25: 4 | AP25: Critical acclaim, with particular praise for A. R. Rahman's soundtrack and Urmila Matondkar's performance. | AQ25: Landmark film credited with a modern sensibility in mid-1990s Hindi cinema; Filmfare wins for Supporting Actor, Music Director, Story, Costume and Choreography; BFJA Best Actor (Hindi) for Aamir Khan. | AR25: SOURCE-030 | AS25: Medium | AT25: Wikipedia's ₹33.4 crore box office (Box Office India) has no nett/gross label and is not entered. Release date 8 September 1995 per Wikipedia; Bollywood Hungama lists 9 August 1995.
A26: FILM-025 | B26: Akele Hum Akele Tum | C26: 35034 | D26: 1995 | E26: 1990s | F26: Hindi | G26: Romantic drama | H26: Musical | I26: 163 | J26: Mansoor Khan | K26: Champak Jain; Ratan Jain | L26: Venus Movies | M26: Mansoor Khan (story, screenplay); Nasir Hussain (dialogue) | N26: Loosely based on Kramer vs. Kramer (1979) | O26: Anu Malik | Q26: Majrooh Sultanpuri | R26: Rohit Kumar | T26: Lead | U26: 1 | V26: Aspiring playback singer | X26: Rohit, an aspiring playback singer, marries Kiran despite her parents' opposition, and her own ambitions recede into housework while his career stalls. Too proud to accept her support, he reads it as pity; she leaves to build a career while he raises their son Sunil alone. She wins custody in court but chooses not to separate father and son, and the family reconciles. | Y26: Success as a singer and a stable family | Z26: Wounded pride as his wife's career overtakes his | AA26: Proud, struggling artist becomes a devoted single father | AB26: Flawed, sympathetic | AC26: Reconciles with Kiran | AD26: Manisha Koirala | AE26: Central | AF26: 9 | AG26: Marriage under strain | AH26: 4.5 | AM26: INR crore | AN26: Successful | AP26: Both leads' performances were acclaimed. | AQ26: Eight Filmfare nominations; soundtrack sold about 2.5 million units, the year's ninth-highest seller. | AR26: SOURCE-031 | AS26: Medium | AT26: Wikipedia's ₹12.37 crore box office (Box Office India) has no nett/gross label and is not entered. Release date 1 December 1995 per Wikipedia; Bollywood Hungama lists 30 November.
A27: FILM-026 | B27: Raja Hindustani | C27: 35384 | D27: 1996 | E27: 1990s | F27: Hindi | G27: Romantic action | I27: 177 | J27: Dharmesh Darshan | K27: Ali Morani; Karim Morani; Bunty Soorma | L27: Cineyug Films | M27: Dharmesh Darshan (story); Robin Bhatt (screenplay); Javed Siddiqui (dialogue) | N27: Inspired by Jab Jab Phool Khile (1965) | O27: Nadeem–Shravan | P27: Surinder Sodhi | Q27: Sameer | R27: Raja Hindustani | T27: Lead | U27: 1 | V27: Taxi driver | W27: Working-class driver in the small hill town of Palankhet | X27: Raja, a proud small-town taxi driver, is hired by the wealthy Aarti, who has come to Palankhet to find traces of her late mother. They fall in love and marry over her father's objections, but her scheming stepmother Shalini convinces each that the other wants out. Separated, Raja takes their infant son, fearing Aarti will keep him away; the deception is exposed and the family reunites. | Y27: Love for Aarti and his self-respect | Z27: The class gap and the stepmother's conspiracy | AA27: Proud working-class lover survives separation and misunderstanding to reunite his family | AB27: Heroic | AC27: Reunited with Aarti and their son | AD27: Karisma Kapoor | AE27: Central | AF27: 10 | AG27: Relationship manipulated by outsiders | AH27: 5.75 | AI27: 43.15 | AJ27: 73.84 | AL27: 76.34 | AM27: INR crore | AN27: All-time blockbuster | AO27: 1 | AP27: Mixed: Anupama Chopra (India Today) found it dated but called Karisma Kapoor its lifeblood; the lead pair's chemistry was praised. | AQ27: Five Filmfare Awards including Best Actor for Aamir Khan; seven Screen Awards; soundtrack sold 11 million copies; fourth-highest domestic grosser of the 1990s. | AR27: SOURCE-032 | AS27: Medium | AT27: All commercial figures from Box Office India via Wikipedia. Overseas gross is not stated separately and is not derived.
A28: FILM-027 | B28: Ishq | C28: 35762 | D28: 1997 | E28: 1990s | F28: Hindi | G28: Romantic comedy | H28: Masala | I28: 168 | J28: Indra Kumar | K28: Gordhan Tanwani | L28: Baba Films | M28: Praful Parekh, Rajeev Kaul (story, screenplay); Tanveer Khan (dialogue) | O28: Anu Malik | P28: Surinder Sodhi | Q28: Rahat Indori; Javed Akhtar | R28: Raja | T28: Co-lead | U28: 1 | V28: Mechanic | W28: Working-class; best friend of the wealthy Ajay | X28: Raja, a working-class mechanic, is best friends with the rich Ajay. Raja falls for Madhu, the heiress whom the fathers want Ajay to marry, while Ajay loves the poor Kajal. Both fathers, contemptuous of the poor, use bribes and fake photographs to turn the couples against each other. Raja exposes the scheme, and Ajay and Madhu reach the departing ship just in time to reunite with their true partners. | Y28: Love for Madhu and loyalty to Ajay | Z28: Two rich fathers' schemes against cross-class marriages | AA28: Comic underdog outwits the fathers | AB28: Heroic | AC28: United with Madhu | AD28: Juhi Chawla; Kajol | AE28: Central | AF28: 8 | AG28: United couple versus external world | AH28: 11 | AI28: 24.93 | AL28: 45.61 | AM28: INR crore | AN28: Commercial success | AO28: 3 | AP28: Mixed to positive; praised for humour, soundtrack and performances, criticised for story and screenplay. | AQ28: Soundtrack sold about 3 million units; remade in Kannada as Snehana Preethina (2007). | AR28: SOURCE-033 | AS28: Medium | AT28: Raja is paired with Madhu (Juhi Chawla) and Ajay (Ajay Devgn) with Kajal (Kajol), per the verbatim plot and cast lines. Commercial figures from Box Office India via Wikipedia.
A29: FILM-028 | B29: Ghulam | C29: 35965 | D29: 1998 | E29: 1990s | F29: Hindi | G29: Action | H29: Crime drama | I29: 162 | J29: Vikram Bhatt | K29: Mukesh Bhatt | L29: Vishesh Films | M29: Anjum Rajabali | N29: Based on On the Waterfront (1954) | O29: Jatin–Lalit | P29: Amar Haldipur | Q29: Indeevar; Nitin Raikwar; Sameer; Vinod Mahendra | R29: Siddharth "Siddhu" Marathe | T29: Lead | U29: 1 | V29: Amateur boxer and small-time hustler | W29: Mumbai neighbourhood youth; younger brother of Jai, right-hand man to the gangster Ronnie | X29: Siddhu, an aimless amateur boxer, drifts on the edges of the gang run by Ronnie, whom his brother Jai serves. He wins a reckless dare against an oncoming train, falls for Alisha, and unwittingly lures her brother Hari, a social worker, into a fatal ambush. Losing Alisha and then Jai, he confronts his family's history of cowardice, testifies against Ronnie and beats him in a public boxing bout. | Y29: Redemption and standing up to Ronnie | Z29: Loyalty to his brother against his conscience | AA29: Aimless hustler becomes the neighbourhood's champion | AB29: Flawed, redeemed | AC29: Defeats Ronnie and rallies the community | AD29: Rani Mukerji | AE29: Secondary | AF29: 5 | AG29: Romance subordinate to another genre | AH29: 7.5 | AM29: INR crore | AN29: Hit | AP29: A commercial success; the train-race sequence won Filmfare's Best Scene of the Year. | AQ29: Aamir Khan's own song 'Aati Kya Khandala' earned him a Filmfare Best Male Playback Singer nomination. | AR29: SOURCE-034; SOURCE-065 | AS29: Medium | AT29: Wikipedia's ₹24.2 crore box office (Box Office India) has no nett/gross label and is not entered. The train dare and Alisha's link to a motorcycle gang come from web search summaries; Wikipedia records a breakup but not whether the couple reunite.
A30: FILM-029 | B30: Sarfarosh | C30: 36280 | D30: 1999 | E30: 1990s | F30: Hindi | G30: Action thriller | H30: Crime | I30: 163 | J30: John Matthew Matthan | K30: John Matthew Matthan | L30: Cinematt Pictures | M30: John Matthew Matthan (story, screenplay); Hriday Lani, Pathik Vats (dialogue) | N30: Original; drew on 1990s state-sponsored terrorism in India | O30: Jatin–Lalit | P30: Sanjoy Chowdhury | Q30: Israr Ansari; Nida Fazli; Sameer; Indeevar | R30: ACP Ajay Singh Rathod | T30: Lead | U30: 1 | V30: Assistant Commissioner of Police leading a special investigation | W30: Middle-class family scarred by terrorism: brother killed, father left mute | X30: Ajay joins the police after terrorists kill his brother and leave his father unable to speak. As an ACP he tracks an arms-smuggling network while resented by the senior Inspector Saleem, and slowly discovers that his admired friend Gulfam Hassan is a Pakistani intelligence agent. Recovering from wounds, he tricks Gulfam into self-incrimination and destroys the network; his reunion with college crush Seema is a warm secondary thread. | Y30: Fight the terrorism that destroyed his family | Z30: Exposing a trusted friend as the mastermind of the arms network | AA30: Idealistic, inexperienced officer learns to pair integrity with cunning | AB30: Heroic | AC30: Dismantles the network and is honoured in Mumbai | AD30: Sonali Bendre | AE30: Secondary | AF30: 3 | AG30: Romance subordinate to another genre | AH30: 8 | AM30: INR crore | AN30: Commercially successful | AP30: Critical acclaim; Filmfare gave four stars for its characterisation and performances, and Naseeruddin Shah was especially praised. | AQ30: National Film Award for Best Popular Film Providing Wholesome Entertainment; screened at IFFI; remade in Kannada and Telugu. Zee Cine Best Actor for Aamir Khan. | AR30: SOURCE-036 | AS30: Medium | AT30: Wikipedia gives box office of ₹33.46 crore citing Box Office India without a nett/gross label; not entered in a commercial column. Budget ₹8 crore.
A31: FILM-030 | B31: Mann | C31: 36350 | D31: 1999 | E31: 1990s | F31: Hindi | G31: Romantic drama | I31: 140 | J31: Indra Kumar | K31: Indra Kumar; Ashok Thakeria | L31: Maruti International | M31: Aatish Kapadia | N31: Inspired by An Affair to Remember (1957) | O31: Sanjeev–Darshan | Q31: Sameer | R31: Dev Karan Singh | T31: Lead | U31: 1 | V31: Painter | W31: Flamboyant, debt-ridden playboy engaged to a tycoon's daughter for money | X31: Dev, a debt-ridden playboy painter engaged to a tycoon's daughter for money, meets Priya on a cruise; she is engaged too. They fall in love and agree to settle their affairs and meet on Valentine's Day in six months. Dev breaks his engagement and works to succeed, but Priya loses her legs in an accident on the way to meet him and hides it; he discovers the truth and marries her. | Y31: Win Priya and become worthy of her | Z31: Believes Priya rejected him, unaware of her accident | AA31: Mercenary casanova becomes a faithful, self-made artist | AB31: Redeemed | AC31: Marries Priya | AD31: Manisha Koirala | AE31: Central | AF31: 10 | AG31: Frictionless idealized romance | AH31: 14 | AM31: INR crore | AN31: Profitable | AP31: Positive reviews; the soundtrack was well received but accused of plagiarising international songs. | AQ31: Soundtrack sold about 2.8 million units, the year's sixth-highest seller. | AR31: SOURCE-037; SOURCE-083 | AS31: Medium | AT31: Wikipedia's ₹35.45 crore box office (Box Office India) has no nett/gross label and is not entered. Dev's broken engagement to Anita Singhania (Deepti Bhatnagar) is recorded here rather than as a Romances row. Indra Kumar's Wikipedia article calls Mann a commercial failure, contradicting the film article's 'profitable'; no verdict entered.
A32: FILM-031 | B32: Earth | C32: 36413 | D32: 1999 | E32: 1990s | F32: Hindi | G32: Period drama | H32: Romance | I32: 101 | J32: Deepa Mehta | K32: Anne Masson; Deepa Mehta | M32: Deepa Mehta | N32: Based on Bapsi Sidhwa's novel Cracking India (first published as Ice Candy Man) | O32: A. R. Rahman | Q32: Javed Akhtar | R32: Dil Navaz, the Ice Candy Man | T32: Co-lead | U32: 1 | V32: Ice-candy seller | W32: Muslim man in 1947 Lahore, part of a mixed-faith circle of friends | X32: Dil Navaz, the Ice Candy Man, belongs to a mixed-faith circle gathered around Shanta, a nanny in Lahore, and competes for her with Hassan, the masseur she plans to marry. The sight of a train of massacred refugees during Partition turns his hurt into communal hatred. He tricks the child Lenny into revealing where Shanta is hiding, delivering her to a mob. | Y32: Win Shanta | Z32: Rejected love and grief poisoned by Partition violence | AA32: Charming suitor becomes a vengeful betrayer | AB32: Becomes antagonist | AC32: Betrays Shanta to a mob | AD32: Nandita Das | AE32: Major | AF32: 7 | AG32: Love triangle | AP32: Strong international reviews (86% on Rotten Tomatoes); Roger Ebert gave three of four stars, and Rediff called it probably the best performance of Aamir Khan's life. | AQ32: India's submission for the Academy Award for Best Foreign Language Film; Filmfare debut awards for Rahul Khanna and Nandita Das. | AR32: SOURCE-035; SOURCE-002 | AS32: Medium | AT32: Indo-Canadian production. Premiered at the Toronto festival on 11 September 1998 (Wikipedia lists it as a 1998 film); released in India as 1947: Earth on 10 September 1999 (Bollywood Hungama), used as the primary release date. Box-office figures not found.
A33: FILM-032 | B33: Mela | C33: 36532 | D33: 2000 | E33: 2000s | F33: Hindi | G33: Masala | H33: Action | I33: 172 | J33: Dharmesh Darshan | K33: Ganesh Jain | L33: Venus Movies | M33: Suneel Darshan (story); Neeraj Vora, Sanjeev Duggal, Robin Bhatt (screenplay); Neeraj Vora, Dharmesh Darshan (dialogue) | N33: Original; the director cited Caravan (1971) as an inspiration | O33: Anu Malik; Rajesh Roshan; Lesle Lewis | P33: Surinder Sodhi | Q33: Dev Kohli; Dharmesh Darshan; Sameer | R33: Kishan Pyare | T33: Lead | U33: 1 | V33: Touring theatre and dance-show performer | W33: Performer in a travelling troupe with his partner Shankar | X33: Kishan, a touring performer, first meets Roopa when she steals his clothes, then fights off goons harassing her and makes her the heroine of his dance show. Roopa feigns love to win his help against the bandit Gujjar Singh, who killed her brother and wants her as his mistress. Heartbroken when she confesses, Kishan leaves, then returns with a police ally to trap and defeat Gujjar. | Y33: Love for Roopa | Z33: The bandit Gujjar Singh and Roopa's strategic deception | AA33: Carefree entertainer becomes a protector | AB33: Heroic | AC33: Defeats Gujjar and ends with Roopa | AD33: Twinkle Khanna | AE33: Major | AF33: 7 | AG33: Relationship damaged by mistrust | AM33: INR crore | AP33: Mixed reviews; Rediff called Aamir Khan the film's saving grace, while song placement and Twinkle Khanna's dubbed voice were criticised. | AR33: SOURCE-038; SOURCE-095 | AS33: Medium | AT33: Wikipedia gives 'est. ₹18 crore' budget and 'est. ₹25 crore' box office (Box Office India) without a nett/gross label; neither is entered because both are estimates and the box-office measure is unlabeled. Aishwarya Rai appears specially as Champakali, paired with Shankar (Faisal Khan). Dharmesh Darshan's Wikipedia article calls Mela a major commercial disaster with highly negative reviews; no verdict entered.
